{
    "timestamp": "2025-04-12 11:08:01",
    "client_ip": "127.0.0.1",
    "method": "POST",
    "url": "http://localhost:8000/likes/",
    "headers": {
        "host": "localhost:8000",
        "connection": "keep-alive",
        "content-length": "34",
        "sec-ch-ua-platform": "\"Windows\"",
        "user-agent": "Mozilla/5.0 (Windows NT 10.0; Win64; x64) AppleWebKit/537.36 (KHTML, like Gecko) Chrome/132.0.0.0 YaBrowser/25.2.0.0 Safari/537.36",
        "accept": "application/json",
        "sec-ch-ua": "\"Not A(Brand\";v=\"8\", \"Chromium\";v=\"132\", \"YaBrowser\";v=\"25.2\", \"Yowser\";v=\"2.5\"",
        "content-type": "application/json",
        "sec-ch-ua-mobile": "?0",
        "origin": "http://localhost:8000",
        "sec-fetch-site": "same-origin",
        "sec-fetch-mode": "cors",
        "sec-fetch-dest": "empty",
        "referer": "http://localhost:8000/docs",
        "accept-encoding": "gzip, deflate, br, zstd",
        "accept-language": "ru,en;q=0.9"
    },
    "error_type": "ResponseValidationError",
    "error_message": "3 validation errors:\n  {'type': 'get_attribute_error', 'loc': ('response', 'post_id'), 'msg': 'Error extracting attribute: PendingRollbackError: This Session\\'s transaction has been rolled back due to a previous exception during flush. To begin a new transaction with this Session, first issue Session.rollback(). Original exception was: (psycopg2.errors.UniqueViolation) duplicate key value violates unique constraint \"tags_for_user_table_pkey\"\\nDETAIL:  Key (id)=(4) already exists.\\n\\n[SQL: INSERT INTO tags_for_user_table (id, user_id, tag_id) VALUES (%(id__0)s, %(user_id__0)s, %(tag_id__0)s), (%(id__1)s, %(user_id__1)s, %(tag_id__1)s), (%(id__2)s, %(user_id__2)s, %(tag_id__2)s), (%(id__3)s, %(user_id__3)s, %(tag_id__3)s), (%(id__4)s, %(user_id__4)s, %(tag_id__4)s), (%(id__5)s, %(user_id__5)s, %(tag_id__5)s), (%(id__6)s, %(user_id__6)s, %(tag_id__6)s), (%(id__7)s, %(user_id__7)s, %(tag_id__7)s), (%(id__8)s, %(user_id__8)s, %(tag_id__8)s), (%(id__9)s, %(user_id__9)s, %(tag_id__9)s)]\\n[parameters: {\\'id__0\\': 4, \\'tag_id__0\\': 6, \\'user_id__0\\': 1, \\'id__1\\': 4, \\'tag_id__1\\': 7, \\'user_id__1\\': 1, \\'id__2\\': 4, \\'tag_id__2\\': 8, \\'user_id__2\\': 1, \\'id__3\\': 4, \\'tag_id__3\\': 9, \\'user_id__3\\': 1, \\'id__4\\': 4, \\'tag_id__4\\': 10, \\'user_id__4\\': 1, \\'id__5\\': 4, \\'tag_id__5\\': 11, \\'user_id__5\\': 1, \\'id__6\\': 4, \\'tag_id__6\\': 12, \\'user_id__6\\': 1, \\'id__7\\': 4, \\'tag_id__7\\': 13, \\'user_id__7\\': 1, \\'id__8\\': 4, \\'tag_id__8\\': 14, \\'user_id__8\\': 1, \\'id__9\\': 4, \\'tag_id__9\\': 15, \\'user_id__9\\': 1}]\\n(Background on this error at: https://sqlalche.me/e/20/gkpj) (Background on this error at: https://sqlalche.me/e/20/7s2a)', 'input': <app.models.models.Like object at 0x00000212D3938980>, 'ctx': {'error': 'PendingRollbackError: This Session\\'s transaction has been rolled back due to a previous exception during flush. To begin a new transaction with this Session, first issue Session.rollback(). Original exception was: (psycopg2.errors.UniqueViolation) duplicate key value violates unique constraint \"tags_for_user_table_pkey\"\\nDETAIL:  Key (id)=(4) already exists.\\n\\n[SQL: INSERT INTO tags_for_user_table (id, user_id, tag_id) VALUES (%(id__0)s, %(user_id__0)s, %(tag_id__0)s), (%(id__1)s, %(user_id__1)s, %(tag_id__1)s), (%(id__2)s, %(user_id__2)s, %(tag_id__2)s), (%(id__3)s, %(user_id__3)s, %(tag_id__3)s), (%(id__4)s, %(user_id__4)s, %(tag_id__4)s), (%(id__5)s, %(user_id__5)s, %(tag_id__5)s), (%(id__6)s, %(user_id__6)s, %(tag_id__6)s), (%(id__7)s, %(user_id__7)s, %(tag_id__7)s), (%(id__8)s, %(user_id__8)s, %(tag_id__8)s), (%(id__9)s, %(user_id__9)s, %(tag_id__9)s)]\\n[parameters: {\\'id__0\\': 4, \\'tag_id__0\\': 6, \\'user_id__0\\': 1, \\'id__1\\': 4, \\'tag_id__1\\': 7, \\'user_id__1\\': 1, \\'id__2\\': 4, \\'tag_id__2\\': 8, \\'user_id__2\\': 1, \\'id__3\\': 4, \\'tag_id__3\\': 9, \\'user_id__3\\': 1, \\'id__4\\': 4, \\'tag_id__4\\': 10, \\'user_id__4\\': 1, \\'id__5\\': 4, \\'tag_id__5\\': 11, \\'user_id__5\\': 1, \\'id__6\\': 4, \\'tag_id__6\\': 12, \\'user_id__6\\': 1, \\'id__7\\': 4, \\'tag_id__7\\': 13, \\'user_id__7\\': 1, \\'id__8\\': 4, \\'tag_id__8\\': 14, \\'user_id__8\\': 1, \\'id__9\\': 4, \\'tag_id__9\\': 15, \\'user_id__9\\': 1}]\\n(Background on this error at: https://sqlalche.me/e/20/gkpj) (Background on this error at: https://sqlalche.me/e/20/7s2a)'}}\n  {'type': 'get_attribute_error', 'loc': ('response', 'user_id'), 'msg': 'Error extracting attribute: PendingRollbackError: This Session\\'s transaction has been rolled back due to a previous exception during flush. To begin a new transaction with this Session, first issue Session.rollback(). Original exception was: (psycopg2.errors.UniqueViolation) duplicate key value violates unique constraint \"tags_for_user_table_pkey\"\\nDETAIL:  Key (id)=(4) already exists.\\n\\n[SQL: INSERT INTO tags_for_user_table (id, user_id, tag_id) VALUES (%(id__0)s, %(user_id__0)s, %(tag_id__0)s), (%(id__1)s, %(user_id__1)s, %(tag_id__1)s), (%(id__2)s, %(user_id__2)s, %(tag_id__2)s), (%(id__3)s, %(user_id__3)s, %(tag_id__3)s), (%(id__4)s, %(user_id__4)s, %(tag_id__4)s), (%(id__5)s, %(user_id__5)s, %(tag_id__5)s), (%(id__6)s, %(user_id__6)s, %(tag_id__6)s), (%(id__7)s, %(user_id__7)s, %(tag_id__7)s), (%(id__8)s, %(user_id__8)s, %(tag_id__8)s), (%(id__9)s, %(user_id__9)s, %(tag_id__9)s)]\\n[parameters: {\\'id__0\\': 4, \\'tag_id__0\\': 6, \\'user_id__0\\': 1, \\'id__1\\': 4, \\'tag_id__1\\': 7, \\'user_id__1\\': 1, \\'id__2\\': 4, \\'tag_id__2\\': 8, \\'user_id__2\\': 1, \\'id__3\\': 4, \\'tag_id__3\\': 9, \\'user_id__3\\': 1, \\'id__4\\': 4, \\'tag_id__4\\': 10, \\'user_id__4\\': 1, \\'id__5\\': 4, \\'tag_id__5\\': 11, \\'user_id__5\\': 1, \\'id__6\\': 4, \\'tag_id__6\\': 12, \\'user_id__6\\': 1, \\'id__7\\': 4, \\'tag_id__7\\': 13, \\'user_id__7\\': 1, \\'id__8\\': 4, \\'tag_id__8\\': 14, \\'user_id__8\\': 1, \\'id__9\\': 4, \\'tag_id__9\\': 15, \\'user_id__9\\': 1}]\\n(Background on this error at: https://sqlalche.me/e/20/gkpj) (Background on this error at: https://sqlalche.me/e/20/7s2a)', 'input': <app.models.models.Like object at 0x00000212D3938980>, 'ctx': {'error': 'PendingRollbackError: This Session\\'s transaction has been rolled back due to a previous exception during flush. To begin a new transaction with this Session, first issue Session.rollback(). Original exception was: (psycopg2.errors.UniqueViolation) duplicate key value violates unique constraint \"tags_for_user_table_pkey\"\\nDETAIL:  Key (id)=(4) already exists.\\n\\n[SQL: INSERT INTO tags_for_user_table (id, user_id, tag_id) VALUES (%(id__0)s, %(user_id__0)s, %(tag_id__0)s), (%(id__1)s, %(user_id__1)s, %(tag_id__1)s), (%(id__2)s, %(user_id__2)s, %(tag_id__2)s), (%(id__3)s, %(user_id__3)s, %(tag_id__3)s), (%(id__4)s, %(user_id__4)s, %(tag_id__4)s), (%(id__5)s, %(user_id__5)s, %(tag_id__5)s), (%(id__6)s, %(user_id__6)s, %(tag_id__6)s), (%(id__7)s, %(user_id__7)s, %(tag_id__7)s), (%(id__8)s, %(user_id__8)s, %(tag_id__8)s), (%(id__9)s, %(user_id__9)s, %(tag_id__9)s)]\\n[parameters: {\\'id__0\\': 4, \\'tag_id__0\\': 6, \\'user_id__0\\': 1, \\'id__1\\': 4, \\'tag_id__1\\': 7, \\'user_id__1\\': 1, \\'id__2\\': 4, \\'tag_id__2\\': 8, \\'user_id__2\\': 1, \\'id__3\\': 4, \\'tag_id__3\\': 9, \\'user_id__3\\': 1, \\'id__4\\': 4, \\'tag_id__4\\': 10, \\'user_id__4\\': 1, \\'id__5\\': 4, \\'tag_id__5\\': 11, \\'user_id__5\\': 1, \\'id__6\\': 4, \\'tag_id__6\\': 12, \\'user_id__6\\': 1, \\'id__7\\': 4, \\'tag_id__7\\': 13, \\'user_id__7\\': 1, \\'id__8\\': 4, \\'tag_id__8\\': 14, \\'user_id__8\\': 1, \\'id__9\\': 4, \\'tag_id__9\\': 15, \\'user_id__9\\': 1}]\\n(Background on this error at: https://sqlalche.me/e/20/gkpj) (Background on this error at: https://sqlalche.me/e/20/7s2a)'}}\n  {'type': 'get_attribute_error', 'loc': ('response', 'like_id'), 'msg': 'Error extracting attribute: PendingRollbackError: This Session\\'s transaction has been rolled back due to a previous exception during flush. To begin a new transaction with this Session, first issue Session.rollback(). Original exception was: (psycopg2.errors.UniqueViolation) duplicate key value violates unique constraint \"tags_for_user_table_pkey\"\\nDETAIL:  Key (id)=(4) already exists.\\n\\n[SQL: INSERT INTO tags_for_user_table (id, user_id, tag_id) VALUES (%(id__0)s, %(user_id__0)s, %(tag_id__0)s), (%(id__1)s, %(user_id__1)s, %(tag_id__1)s), (%(id__2)s, %(user_id__2)s, %(tag_id__2)s), (%(id__3)s, %(user_id__3)s, %(tag_id__3)s), (%(id__4)s, %(user_id__4)s, %(tag_id__4)s), (%(id__5)s, %(user_id__5)s, %(tag_id__5)s), (%(id__6)s, %(user_id__6)s, %(tag_id__6)s), (%(id__7)s, %(user_id__7)s, %(tag_id__7)s), (%(id__8)s, %(user_id__8)s, %(tag_id__8)s), (%(id__9)s, %(user_id__9)s, %(tag_id__9)s)]\\n[parameters: {\\'id__0\\': 4, \\'tag_id__0\\': 6, \\'user_id__0\\': 1, \\'id__1\\': 4, \\'tag_id__1\\': 7, \\'user_id__1\\': 1, \\'id__2\\': 4, \\'tag_id__2\\': 8, \\'user_id__2\\': 1, \\'id__3\\': 4, \\'tag_id__3\\': 9, \\'user_id__3\\': 1, \\'id__4\\': 4, \\'tag_id__4\\': 10, \\'user_id__4\\': 1, \\'id__5\\': 4, \\'tag_id__5\\': 11, \\'user_id__5\\': 1, \\'id__6\\': 4, \\'tag_id__6\\': 12, \\'user_id__6\\': 1, \\'id__7\\': 4, \\'tag_id__7\\': 13, \\'user_id__7\\': 1, \\'id__8\\': 4, \\'tag_id__8\\': 14, \\'user_id__8\\': 1, \\'id__9\\': 4, \\'tag_id__9\\': 15, \\'user_id__9\\': 1}]\\n(Background on this error at: https://sqlalche.me/e/20/gkpj) (Background on this error at: https://sqlalche.me/e/20/7s2a)', 'input': <app.models.models.Like object at 0x00000212D3938980>, 'ctx': {'error': 'PendingRollbackError: This Session\\'s transaction has been rolled back due to a previous exception during flush. To begin a new transaction with this Session, first issue Session.rollback(). Original exception was: (psycopg2.errors.UniqueViolation) duplicate key value violates unique constraint \"tags_for_user_table_pkey\"\\nDETAIL:  Key (id)=(4) already exists.\\n\\n[SQL: INSERT INTO tags_for_user_table (id, user_id, tag_id) VALUES (%(id__0)s, %(user_id__0)s, %(tag_id__0)s), (%(id__1)s, %(user_id__1)s, %(tag_id__1)s), (%(id__2)s, %(user_id__2)s, %(tag_id__2)s), (%(id__3)s, %(user_id__3)s, %(tag_id__3)s), (%(id__4)s, %(user_id__4)s, %(tag_id__4)s), (%(id__5)s, %(user_id__5)s, %(tag_id__5)s), (%(id__6)s, %(user_id__6)s, %(tag_id__6)s), (%(id__7)s, %(user_id__7)s, %(tag_id__7)s), (%(id__8)s, %(user_id__8)s, %(tag_id__8)s), (%(id__9)s, %(user_id__9)s, %(tag_id__9)s)]\\n[parameters: {\\'id__0\\': 4, \\'tag_id__0\\': 6, \\'user_id__0\\': 1, \\'id__1\\': 4, \\'tag_id__1\\': 7, \\'user_id__1\\': 1, \\'id__2\\': 4, \\'tag_id__2\\': 8, \\'user_id__2\\': 1, \\'id__3\\': 4, \\'tag_id__3\\': 9, \\'user_id__3\\': 1, \\'id__4\\': 4, \\'tag_id__4\\': 10, \\'user_id__4\\': 1, \\'id__5\\': 4, \\'tag_id__5\\': 11, \\'user_id__5\\': 1, \\'id__6\\': 4, \\'tag_id__6\\': 12, \\'user_id__6\\': 1, \\'id__7\\': 4, \\'tag_id__7\\': 13, \\'user_id__7\\': 1, \\'id__8\\': 4, \\'tag_id__8\\': 14, \\'user_id__8\\': 1, \\'id__9\\': 4, \\'tag_id__9\\': 15, \\'user_id__9\\': 1}]\\n(Background on this error at: https://sqlalche.me/e/20/gkpj) (Background on this error at: https://sqlalche.me/e/20/7s2a)'}}\n",
    "traceback": "  + Exception Group Traceback (most recent call last):\n  |   File \"D:\\\u041f\u0440\u043e\u0435\u043a\u0442\u044b\\Threads_Hack\\venv\\Lib\\site-packages\\starlette\\_utils.py\", line 76, in collapse_excgroups\n  |     yield\n  |   File \"D:\\\u041f\u0440\u043e\u0435\u043a\u0442\u044b\\Threads_Hack\\venv\\Lib\\site-packages\\starlette\\middleware\\base.py\", line 174, in __call__\n  |     async with anyio.create_task_group() as task_group:\n  |                ~~~~~~~~~~~~~~~~~~~~~~~^^\n  |   File \"D:\\\u041f\u0440\u043e\u0435\u043a\u0442\u044b\\Threads_Hack\\venv\\Lib\\site-packages\\anyio\\_backends\\_asyncio.py\", line 772, in __aexit__\n  |     raise BaseExceptionGroup(\n  |         \"unhandled errors in a TaskGroup\", self._exceptions\n  |     ) from None\n  | ExceptionGroup: unhandled errors in a TaskGroup (1 sub-exception)\n  +-+---------------- 1 ----------------\n    | Traceback (most recent call last):\n    |   File \"D:\\\u041f\u0440\u043e\u0435\u043a\u0442\u044b\\Threads_Hack\\venv\\Lib\\site-packages\\starlette\\middleware\\errors.py\", line 165, in __call__\n    |     await self.app(scope, receive, _send)\n    |   File \"D:\\\u041f\u0440\u043e\u0435\u043a\u0442\u044b\\Threads_Hack\\venv\\Lib\\site-packages\\starlette\\middleware\\base.py\", line 173, in __call__\n    |     with recv_stream, send_stream, collapse_excgroups():\n    |                                    ~~~~~~~~~~~~~~~~~~^^\n    |   File \"C:\\Python313\\Lib\\contextlib.py\", line 162, in __exit__\n    |     self.gen.throw(value)\n    |     ~~~~~~~~~~~~~~^^^^^^^\n    |   File \"D:\\\u041f\u0440\u043e\u0435\u043a\u0442\u044b\\Threads_Hack\\venv\\Lib\\site-packages\\starlette\\_utils.py\", line 82, in collapse_excgroups\n    |     raise exc\n    |   File \"D:\\\u041f\u0440\u043e\u0435\u043a\u0442\u044b\\Threads_Hack\\venv\\Lib\\site-packages\\starlette\\middleware\\base.py\", line 175, in __call__\n    |     response = await self.dispatch_func(request, call_next)\n    |                ^^^^^^^^^^^^^^^^^^^^^^^^^^^^^^^^^^^^^^^^^^^^\n    |   File \"D:\\\u041f\u0440\u043e\u0435\u043a\u0442\u044b\\Threads_Hack\\app\\utils\\middleware.py\", line 17, in dispatch\n    |     response = await call_next(request)\n    |                ^^^^^^^^^^^^^^^^^^^^^^^^\n    |   File \"D:\\\u041f\u0440\u043e\u0435\u043a\u0442\u044b\\Threads_Hack\\venv\\Lib\\site-packages\\starlette\\middleware\\base.py\", line 153, in call_next\n    |     raise app_exc\n    |   File \"D:\\\u041f\u0440\u043e\u0435\u043a\u0442\u044b\\Threads_Hack\\venv\\Lib\\site-packages\\starlette\\middleware\\base.py\", line 140, in coro\n    |     await self.app(scope, receive_or_disconnect, send_no_error)\n    |   File \"D:\\\u041f\u0440\u043e\u0435\u043a\u0442\u044b\\Threads_Hack\\venv\\Lib\\site-packages\\starlette\\middleware\\exceptions.py\", line 62, in __call__\n    |     await wrap_app_handling_exceptions(self.app, conn)(scope, receive, send)\n    |   File \"D:\\\u041f\u0440\u043e\u0435\u043a\u0442\u044b\\Threads_Hack\\venv\\Lib\\site-packages\\starlette\\_exception_handler.py\", line 53, in wrapped_app\n    |     raise exc\n    |   File \"D:\\\u041f\u0440\u043e\u0435\u043a\u0442\u044b\\Threads_Hack\\venv\\Lib\\site-packages\\starlette\\_exception_handler.py\", line 42, in wrapped_app\n    |     await app(scope, receive, sender)\n    |   File \"D:\\\u041f\u0440\u043e\u0435\u043a\u0442\u044b\\Threads_Hack\\venv\\Lib\\site-packages\\starlette\\routing.py\", line 714, in __call__\n    |     await self.middleware_stack(scope, receive, send)\n    |   File \"D:\\\u041f\u0440\u043e\u0435\u043a\u0442\u044b\\Threads_Hack\\venv\\Lib\\site-packages\\starlette\\routing.py\", line 734, in app\n    |     await route.handle(scope, receive, send)\n    |   File \"D:\\\u041f\u0440\u043e\u0435\u043a\u0442\u044b\\Threads_Hack\\venv\\Lib\\site-packages\\starlette\\routing.py\", line 288, in handle\n    |     await self.app(scope, receive, send)\n    |   File \"D:\\\u041f\u0440\u043e\u0435\u043a\u0442\u044b\\Threads_Hack\\venv\\Lib\\site-packages\\starlette\\routing.py\", line 76, in app\n    |     await wrap_app_handling_exceptions(app, request)(scope, receive, send)\n    |   File \"D:\\\u041f\u0440\u043e\u0435\u043a\u0442\u044b\\Threads_Hack\\venv\\Lib\\site-packages\\starlette\\_exception_handler.py\", line 53, in wrapped_app\n    |     raise exc\n    |   File \"D:\\\u041f\u0440\u043e\u0435\u043a\u0442\u044b\\Threads_Hack\\venv\\Lib\\site-packages\\starlette\\_exception_handler.py\", line 42, in wrapped_app\n    |     await app(scope, receive, sender)\n    |   File \"D:\\\u041f\u0440\u043e\u0435\u043a\u0442\u044b\\Threads_Hack\\venv\\Lib\\site-packages\\starlette\\routing.py\", line 73, in app\n    |     response = await f(request)\n    |                ^^^^^^^^^^^^^^^^\n    |   File \"D:\\\u041f\u0440\u043e\u0435\u043a\u0442\u044b\\Threads_Hack\\venv\\Lib\\site-packages\\fastapi\\routing.py\", line 327, in app\n    |     content = await serialize_response(\n    |               ^^^^^^^^^^^^^^^^^^^^^^^^^\n    |     ...<9 lines>...\n    |     )\n    |     ^\n    |   File \"D:\\\u041f\u0440\u043e\u0435\u043a\u0442\u044b\\Threads_Hack\\venv\\Lib\\site-packages\\fastapi\\routing.py\", line 176, in serialize_response\n    |     raise ResponseValidationError(\n    |         errors=_normalize_errors(errors), body=response_content\n    |     )\n    | fastapi.exceptions.ResponseValidationError: 3 validation errors:\n    |   {'type': 'get_attribute_error', 'loc': ('response', 'post_id'), 'msg': 'Error extracting attribute: PendingRollbackError: This Session\\'s transaction has been rolled back due to a previous exception during flush. To begin a new transaction with this Session, first issue Session.rollback(). Original exception was: (psycopg2.errors.UniqueViolation) duplicate key value violates unique constraint \"tags_for_user_table_pkey\"\\nDETAIL:  Key (id)=(4) already exists.\\n\\n[SQL: INSERT INTO tags_for_user_table (id, user_id, tag_id) VALUES (%(id__0)s, %(user_id__0)s, %(tag_id__0)s), (%(id__1)s, %(user_id__1)s, %(tag_id__1)s), (%(id__2)s, %(user_id__2)s, %(tag_id__2)s), (%(id__3)s, %(user_id__3)s, %(tag_id__3)s), (%(id__4)s, %(user_id__4)s, %(tag_id__4)s), (%(id__5)s, %(user_id__5)s, %(tag_id__5)s), (%(id__6)s, %(user_id__6)s, %(tag_id__6)s), (%(id__7)s, %(user_id__7)s, %(tag_id__7)s), (%(id__8)s, %(user_id__8)s, %(tag_id__8)s), (%(id__9)s, %(user_id__9)s, %(tag_id__9)s)]\\n[parameters: {\\'id__0\\': 4, \\'tag_id__0\\': 6, \\'user_id__0\\': 1, \\'id__1\\': 4, \\'tag_id__1\\': 7, \\'user_id__1\\': 1, \\'id__2\\': 4, \\'tag_id__2\\': 8, \\'user_id__2\\': 1, \\'id__3\\': 4, \\'tag_id__3\\': 9, \\'user_id__3\\': 1, \\'id__4\\': 4, \\'tag_id__4\\': 10, \\'user_id__4\\': 1, \\'id__5\\': 4, \\'tag_id__5\\': 11, \\'user_id__5\\': 1, \\'id__6\\': 4, \\'tag_id__6\\': 12, \\'user_id__6\\': 1, \\'id__7\\': 4, \\'tag_id__7\\': 13, \\'user_id__7\\': 1, \\'id__8\\': 4, \\'tag_id__8\\': 14, \\'user_id__8\\': 1, \\'id__9\\': 4, \\'tag_id__9\\': 15, \\'user_id__9\\': 1}]\\n(Background on this error at: https://sqlalche.me/e/20/gkpj) (Background on this error at: https://sqlalche.me/e/20/7s2a)', 'input': <app.models.models.Like object at 0x00000212D3938980>, 'ctx': {'error': 'PendingRollbackError: This Session\\'s transaction has been rolled back due to a previous exception during flush. To begin a new transaction with this Session, first issue Session.rollback(). Original exception was: (psycopg2.errors.UniqueViolation) duplicate key value violates unique constraint \"tags_for_user_table_pkey\"\\nDETAIL:  Key (id)=(4) already exists.\\n\\n[SQL: INSERT INTO tags_for_user_table (id, user_id, tag_id) VALUES (%(id__0)s, %(user_id__0)s, %(tag_id__0)s), (%(id__1)s, %(user_id__1)s, %(tag_id__1)s), (%(id__2)s, %(user_id__2)s, %(tag_id__2)s), (%(id__3)s, %(user_id__3)s, %(tag_id__3)s), (%(id__4)s, %(user_id__4)s, %(tag_id__4)s), (%(id__5)s, %(user_id__5)s, %(tag_id__5)s), (%(id__6)s, %(user_id__6)s, %(tag_id__6)s), (%(id__7)s, %(user_id__7)s, %(tag_id__7)s), (%(id__8)s, %(user_id__8)s, %(tag_id__8)s), (%(id__9)s, %(user_id__9)s, %(tag_id__9)s)]\\n[parameters: {\\'id__0\\': 4, \\'tag_id__0\\': 6, \\'user_id__0\\': 1, \\'id__1\\': 4, \\'tag_id__1\\': 7, \\'user_id__1\\': 1, \\'id__2\\': 4, \\'tag_id__2\\': 8, \\'user_id__2\\': 1, \\'id__3\\': 4, \\'tag_id__3\\': 9, \\'user_id__3\\': 1, \\'id__4\\': 4, \\'tag_id__4\\': 10, \\'user_id__4\\': 1, \\'id__5\\': 4, \\'tag_id__5\\': 11, \\'user_id__5\\': 1, \\'id__6\\': 4, \\'tag_id__6\\': 12, \\'user_id__6\\': 1, \\'id__7\\': 4, \\'tag_id__7\\': 13, \\'user_id__7\\': 1, \\'id__8\\': 4, \\'tag_id__8\\': 14, \\'user_id__8\\': 1, \\'id__9\\': 4, \\'tag_id__9\\': 15, \\'user_id__9\\': 1}]\\n(Background on this error at: https://sqlalche.me/e/20/gkpj) (Background on this error at: https://sqlalche.me/e/20/7s2a)'}}\n    |   {'type': 'get_attribute_error', 'loc': ('response', 'user_id'), 'msg': 'Error extracting attribute: PendingRollbackError: This Session\\'s transaction has been rolled back due to a previous exception during flush. To begin a new transaction with this Session, first issue Session.rollback(). Original exception was: (psycopg2.errors.UniqueViolation) duplicate key value violates unique constraint \"tags_for_user_table_pkey\"\\nDETAIL:  Key (id)=(4) already exists.\\n\\n[SQL: INSERT INTO tags_for_user_table (id, user_id, tag_id) VALUES (%(id__0)s, %(user_id__0)s, %(tag_id__0)s), (%(id__1)s, %(user_id__1)s, %(tag_id__1)s), (%(id__2)s, %(user_id__2)s, %(tag_id__2)s), (%(id__3)s, %(user_id__3)s, %(tag_id__3)s), (%(id__4)s, %(user_id__4)s, %(tag_id__4)s), (%(id__5)s, %(user_id__5)s, %(tag_id__5)s), (%(id__6)s, %(user_id__6)s, %(tag_id__6)s), (%(id__7)s, %(user_id__7)s, %(tag_id__7)s), (%(id__8)s, %(user_id__8)s, %(tag_id__8)s), (%(id__9)s, %(user_id__9)s, %(tag_id__9)s)]\\n[parameters: {\\'id__0\\': 4, \\'tag_id__0\\': 6, \\'user_id__0\\': 1, \\'id__1\\': 4, \\'tag_id__1\\': 7, \\'user_id__1\\': 1, \\'id__2\\': 4, \\'tag_id__2\\': 8, \\'user_id__2\\': 1, \\'id__3\\': 4, \\'tag_id__3\\': 9, \\'user_id__3\\': 1, \\'id__4\\': 4, \\'tag_id__4\\': 10, \\'user_id__4\\': 1, \\'id__5\\': 4, \\'tag_id__5\\': 11, \\'user_id__5\\': 1, \\'id__6\\': 4, \\'tag_id__6\\': 12, \\'user_id__6\\': 1, \\'id__7\\': 4, \\'tag_id__7\\': 13, \\'user_id__7\\': 1, \\'id__8\\': 4, \\'tag_id__8\\': 14, \\'user_id__8\\': 1, \\'id__9\\': 4, \\'tag_id__9\\': 15, \\'user_id__9\\': 1}]\\n(Background on this error at: https://sqlalche.me/e/20/gkpj) (Background on this error at: https://sqlalche.me/e/20/7s2a)', 'input': <app.models.models.Like object at 0x00000212D3938980>, 'ctx': {'error': 'PendingRollbackError: This Session\\'s transaction has been rolled back due to a previous exception during flush. To begin a new transaction with this Session, first issue Session.rollback(). Original exception was: (psycopg2.errors.UniqueViolation) duplicate key value violates unique constraint \"tags_for_user_table_pkey\"\\nDETAIL:  Key (id)=(4) already exists.\\n\\n[SQL: INSERT INTO tags_for_user_table (id, user_id, tag_id) VALUES (%(id__0)s, %(user_id__0)s, %(tag_id__0)s), (%(id__1)s, %(user_id__1)s, %(tag_id__1)s), (%(id__2)s, %(user_id__2)s, %(tag_id__2)s), (%(id__3)s, %(user_id__3)s, %(tag_id__3)s), (%(id__4)s, %(user_id__4)s, %(tag_id__4)s), (%(id__5)s, %(user_id__5)s, %(tag_id__5)s), (%(id__6)s, %(user_id__6)s, %(tag_id__6)s), (%(id__7)s, %(user_id__7)s, %(tag_id__7)s), (%(id__8)s, %(user_id__8)s, %(tag_id__8)s), (%(id__9)s, %(user_id__9)s, %(tag_id__9)s)]\\n[parameters: {\\'id__0\\': 4, \\'tag_id__0\\': 6, \\'user_id__0\\': 1, \\'id__1\\': 4, \\'tag_id__1\\': 7, \\'user_id__1\\': 1, \\'id__2\\': 4, \\'tag_id__2\\': 8, \\'user_id__2\\': 1, \\'id__3\\': 4, \\'tag_id__3\\': 9, \\'user_id__3\\': 1, \\'id__4\\': 4, \\'tag_id__4\\': 10, \\'user_id__4\\': 1, \\'id__5\\': 4, \\'tag_id__5\\': 11, \\'user_id__5\\': 1, \\'id__6\\': 4, \\'tag_id__6\\': 12, \\'user_id__6\\': 1, \\'id__7\\': 4, \\'tag_id__7\\': 13, \\'user_id__7\\': 1, \\'id__8\\': 4, \\'tag_id__8\\': 14, \\'user_id__8\\': 1, \\'id__9\\': 4, \\'tag_id__9\\': 15, \\'user_id__9\\': 1}]\\n(Background on this error at: https://sqlalche.me/e/20/gkpj) (Background on this error at: https://sqlalche.me/e/20/7s2a)'}}\n    |   {'type': 'get_attribute_error', 'loc': ('response', 'like_id'), 'msg': 'Error extracting attribute: PendingRollbackError: This Session\\'s transaction has been rolled back due to a previous exception during flush. To begin a new transaction with this Session, first issue Session.rollback(). Original exception was: (psycopg2.errors.UniqueViolation) duplicate key value violates unique constraint \"tags_for_user_table_pkey\"\\nDETAIL:  Key (id)=(4) already exists.\\n\\n[SQL: INSERT INTO tags_for_user_table (id, user_id, tag_id) VALUES (%(id__0)s, %(user_id__0)s, %(tag_id__0)s), (%(id__1)s, %(user_id__1)s, %(tag_id__1)s), (%(id__2)s, %(user_id__2)s, %(tag_id__2)s), (%(id__3)s, %(user_id__3)s, %(tag_id__3)s), (%(id__4)s, %(user_id__4)s, %(tag_id__4)s), (%(id__5)s, %(user_id__5)s, %(tag_id__5)s), (%(id__6)s, %(user_id__6)s, %(tag_id__6)s), (%(id__7)s, %(user_id__7)s, %(tag_id__7)s), (%(id__8)s, %(user_id__8)s, %(tag_id__8)s), (%(id__9)s, %(user_id__9)s, %(tag_id__9)s)]\\n[parameters: {\\'id__0\\': 4, \\'tag_id__0\\': 6, \\'user_id__0\\': 1, \\'id__1\\': 4, \\'tag_id__1\\': 7, \\'user_id__1\\': 1, \\'id__2\\': 4, \\'tag_id__2\\': 8, \\'user_id__2\\': 1, \\'id__3\\': 4, \\'tag_id__3\\': 9, \\'user_id__3\\': 1, \\'id__4\\': 4, \\'tag_id__4\\': 10, \\'user_id__4\\': 1, \\'id__5\\': 4, \\'tag_id__5\\': 11, \\'user_id__5\\': 1, \\'id__6\\': 4, \\'tag_id__6\\': 12, \\'user_id__6\\': 1, \\'id__7\\': 4, \\'tag_id__7\\': 13, \\'user_id__7\\': 1, \\'id__8\\': 4, \\'tag_id__8\\': 14, \\'user_id__8\\': 1, \\'id__9\\': 4, \\'tag_id__9\\': 15, \\'user_id__9\\': 1}]\\n(Background on this error at: https://sqlalche.me/e/20/gkpj) (Background on this error at: https://sqlalche.me/e/20/7s2a)', 'input': <app.models.models.Like object at 0x00000212D3938980>, 'ctx': {'error': 'PendingRollbackError: This Session\\'s transaction has been rolled back due to a previous exception during flush. To begin a new transaction with this Session, first issue Session.rollback(). Original exception was: (psycopg2.errors.UniqueViolation) duplicate key value violates unique constraint \"tags_for_user_table_pkey\"\\nDETAIL:  Key (id)=(4) already exists.\\n\\n[SQL: INSERT INTO tags_for_user_table (id, user_id, tag_id) VALUES (%(id__0)s, %(user_id__0)s, %(tag_id__0)s), (%(id__1)s, %(user_id__1)s, %(tag_id__1)s), (%(id__2)s, %(user_id__2)s, %(tag_id__2)s), (%(id__3)s, %(user_id__3)s, %(tag_id__3)s), (%(id__4)s, %(user_id__4)s, %(tag_id__4)s), (%(id__5)s, %(user_id__5)s, %(tag_id__5)s), (%(id__6)s, %(user_id__6)s, %(tag_id__6)s), (%(id__7)s, %(user_id__7)s, %(tag_id__7)s), (%(id__8)s, %(user_id__8)s, %(tag_id__8)s), (%(id__9)s, %(user_id__9)s, %(tag_id__9)s)]\\n[parameters: {\\'id__0\\': 4, \\'tag_id__0\\': 6, \\'user_id__0\\': 1, \\'id__1\\': 4, \\'tag_id__1\\': 7, \\'user_id__1\\': 1, \\'id__2\\': 4, \\'tag_id__2\\': 8, \\'user_id__2\\': 1, \\'id__3\\': 4, \\'tag_id__3\\': 9, \\'user_id__3\\': 1, \\'id__4\\': 4, \\'tag_id__4\\': 10, \\'user_id__4\\': 1, \\'id__5\\': 4, \\'tag_id__5\\': 11, \\'user_id__5\\': 1, \\'id__6\\': 4, \\'tag_id__6\\': 12, \\'user_id__6\\': 1, \\'id__7\\': 4, \\'tag_id__7\\': 13, \\'user_id__7\\': 1, \\'id__8\\': 4, \\'tag_id__8\\': 14, \\'user_id__8\\': 1, \\'id__9\\': 4, \\'tag_id__9\\': 15, \\'user_id__9\\': 1}]\\n(Background on this error at: https://sqlalche.me/e/20/gkpj) (Background on this error at: https://sqlalche.me/e/20/7s2a)'}}\n    | \n    +------------------------------------\n\nDuring handling of the above exception, another exception occurred:\n\nTraceback (most recent call last):\n  File \"D:\\\u041f\u0440\u043e\u0435\u043a\u0442\u044b\\Threads_Hack\\venv\\Lib\\site-packages\\starlette\\middleware\\errors.py\", line 165, in __call__\n    await self.app(scope, receive, _send)\n  File \"D:\\\u041f\u0440\u043e\u0435\u043a\u0442\u044b\\Threads_Hack\\venv\\Lib\\site-packages\\starlette\\middleware\\base.py\", line 173, in __call__\n    with recv_stream, send_stream, collapse_excgroups():\n                                   ~~~~~~~~~~~~~~~~~~^^\n  File \"C:\\Python313\\Lib\\contextlib.py\", line 162, in __exit__\n    self.gen.throw(value)\n    ~~~~~~~~~~~~~~^^^^^^^\n  File \"D:\\\u041f\u0440\u043e\u0435\u043a\u0442\u044b\\Threads_Hack\\venv\\Lib\\site-packages\\starlette\\_utils.py\", line 82, in collapse_excgroups\n    raise exc\n  File \"D:\\\u041f\u0440\u043e\u0435\u043a\u0442\u044b\\Threads_Hack\\venv\\Lib\\site-packages\\starlette\\middleware\\base.py\", line 175, in __call__\n    response = await self.dispatch_func(request, call_next)\n               ^^^^^^^^^^^^^^^^^^^^^^^^^^^^^^^^^^^^^^^^^^^^\n  File \"D:\\\u041f\u0440\u043e\u0435\u043a\u0442\u044b\\Threads_Hack\\app\\utils\\middleware.py\", line 17, in dispatch\n    response = await call_next(request)\n               ^^^^^^^^^^^^^^^^^^^^^^^^\n  File \"D:\\\u041f\u0440\u043e\u0435\u043a\u0442\u044b\\Threads_Hack\\venv\\Lib\\site-packages\\starlette\\middleware\\base.py\", line 153, in call_next\n    raise app_exc\n  File \"D:\\\u041f\u0440\u043e\u0435\u043a\u0442\u044b\\Threads_Hack\\venv\\Lib\\site-packages\\starlette\\middleware\\base.py\", line 140, in coro\n    await self.app(scope, receive_or_disconnect, send_no_error)\n  File \"D:\\\u041f\u0440\u043e\u0435\u043a\u0442\u044b\\Threads_Hack\\venv\\Lib\\site-packages\\starlette\\middleware\\exceptions.py\", line 62, in __call__\n    await wrap_app_handling_exceptions(self.app, conn)(scope, receive, send)\n  File \"D:\\\u041f\u0440\u043e\u0435\u043a\u0442\u044b\\Threads_Hack\\venv\\Lib\\site-packages\\starlette\\_exception_handler.py\", line 53, in wrapped_app\n    raise exc\n  File \"D:\\\u041f\u0440\u043e\u0435\u043a\u0442\u044b\\Threads_Hack\\venv\\Lib\\site-packages\\starlette\\_exception_handler.py\", line 42, in wrapped_app\n    await app(scope, receive, sender)\n  File \"D:\\\u041f\u0440\u043e\u0435\u043a\u0442\u044b\\Threads_Hack\\venv\\Lib\\site-packages\\starlette\\routing.py\", line 714, in __call__\n    await self.middleware_stack(scope, receive, send)\n  File \"D:\\\u041f\u0440\u043e\u0435\u043a\u0442\u044b\\Threads_Hack\\venv\\Lib\\site-packages\\starlette\\routing.py\", line 734, in app\n    await route.handle(scope, receive, send)\n  File \"D:\\\u041f\u0440\u043e\u0435\u043a\u0442\u044b\\Threads_Hack\\venv\\Lib\\site-packages\\starlette\\routing.py\", line 288, in handle\n    await self.app(scope, receive, send)\n  File \"D:\\\u041f\u0440\u043e\u0435\u043a\u0442\u044b\\Threads_Hack\\venv\\Lib\\site-packages\\starlette\\routing.py\", line 76, in app\n    await wrap_app_handling_exceptions(app, request)(scope, receive, send)\n  File \"D:\\\u041f\u0440\u043e\u0435\u043a\u0442\u044b\\Threads_Hack\\venv\\Lib\\site-packages\\starlette\\_exception_handler.py\", line 53, in wrapped_app\n    raise exc\n  File \"D:\\\u041f\u0440\u043e\u0435\u043a\u0442\u044b\\Threads_Hack\\venv\\Lib\\site-packages\\starlette\\_exception_handler.py\", line 42, in wrapped_app\n    await app(scope, receive, sender)\n  File \"D:\\\u041f\u0440\u043e\u0435\u043a\u0442\u044b\\Threads_Hack\\venv\\Lib\\site-packages\\starlette\\routing.py\", line 73, in app\n    response = await f(request)\n               ^^^^^^^^^^^^^^^^\n  File \"D:\\\u041f\u0440\u043e\u0435\u043a\u0442\u044b\\Threads_Hack\\venv\\Lib\\site-packages\\fastapi\\routing.py\", line 327, in app\n    content = await serialize_response(\n              ^^^^^^^^^^^^^^^^^^^^^^^^^\n    ...<9 lines>...\n    )\n    ^\n  File \"D:\\\u041f\u0440\u043e\u0435\u043a\u0442\u044b\\Threads_Hack\\venv\\Lib\\site-packages\\fastapi\\routing.py\", line 176, in serialize_response\n    raise ResponseValidationError(\n        errors=_normalize_errors(errors), body=response_content\n    )\nfastapi.exceptions.ResponseValidationError: 3 validation errors:\n  {'type': 'get_attribute_error', 'loc': ('response', 'post_id'), 'msg': 'Error extracting attribute: PendingRollbackError: This Session\\'s transaction has been rolled back due to a previous exception during flush. To begin a new transaction with this Session, first issue Session.rollback(). Original exception was: (psycopg2.errors.UniqueViolation) duplicate key value violates unique constraint \"tags_for_user_table_pkey\"\\nDETAIL:  Key (id)=(4) already exists.\\n\\n[SQL: INSERT INTO tags_for_user_table (id, user_id, tag_id) VALUES (%(id__0)s, %(user_id__0)s, %(tag_id__0)s), (%(id__1)s, %(user_id__1)s, %(tag_id__1)s), (%(id__2)s, %(user_id__2)s, %(tag_id__2)s), (%(id__3)s, %(user_id__3)s, %(tag_id__3)s), (%(id__4)s, %(user_id__4)s, %(tag_id__4)s), (%(id__5)s, %(user_id__5)s, %(tag_id__5)s), (%(id__6)s, %(user_id__6)s, %(tag_id__6)s), (%(id__7)s, %(user_id__7)s, %(tag_id__7)s), (%(id__8)s, %(user_id__8)s, %(tag_id__8)s), (%(id__9)s, %(user_id__9)s, %(tag_id__9)s)]\\n[parameters: {\\'id__0\\': 4, \\'tag_id__0\\': 6, \\'user_id__0\\': 1, \\'id__1\\': 4, \\'tag_id__1\\': 7, \\'user_id__1\\': 1, \\'id__2\\': 4, \\'tag_id__2\\': 8, \\'user_id__2\\': 1, \\'id__3\\': 4, \\'tag_id__3\\': 9, \\'user_id__3\\': 1, \\'id__4\\': 4, \\'tag_id__4\\': 10, \\'user_id__4\\': 1, \\'id__5\\': 4, \\'tag_id__5\\': 11, \\'user_id__5\\': 1, \\'id__6\\': 4, \\'tag_id__6\\': 12, \\'user_id__6\\': 1, \\'id__7\\': 4, \\'tag_id__7\\': 13, \\'user_id__7\\': 1, \\'id__8\\': 4, \\'tag_id__8\\': 14, \\'user_id__8\\': 1, \\'id__9\\': 4, \\'tag_id__9\\': 15, \\'user_id__9\\': 1}]\\n(Background on this error at: https://sqlalche.me/e/20/gkpj) (Background on this error at: https://sqlalche.me/e/20/7s2a)', 'input': <app.models.models.Like object at 0x00000212D3938980>, 'ctx': {'error': 'PendingRollbackError: This Session\\'s transaction has been rolled back due to a previous exception during flush. To begin a new transaction with this Session, first issue Session.rollback(). Original exception was: (psycopg2.errors.UniqueViolation) duplicate key value violates unique constraint \"tags_for_user_table_pkey\"\\nDETAIL:  Key (id)=(4) already exists.\\n\\n[SQL: INSERT INTO tags_for_user_table (id, user_id, tag_id) VALUES (%(id__0)s, %(user_id__0)s, %(tag_id__0)s), (%(id__1)s, %(user_id__1)s, %(tag_id__1)s), (%(id__2)s, %(user_id__2)s, %(tag_id__2)s), (%(id__3)s, %(user_id__3)s, %(tag_id__3)s), (%(id__4)s, %(user_id__4)s, %(tag_id__4)s), (%(id__5)s, %(user_id__5)s, %(tag_id__5)s), (%(id__6)s, %(user_id__6)s, %(tag_id__6)s), (%(id__7)s, %(user_id__7)s, %(tag_id__7)s), (%(id__8)s, %(user_id__8)s, %(tag_id__8)s), (%(id__9)s, %(user_id__9)s, %(tag_id__9)s)]\\n[parameters: {\\'id__0\\': 4, \\'tag_id__0\\': 6, \\'user_id__0\\': 1, \\'id__1\\': 4, \\'tag_id__1\\': 7, \\'user_id__1\\': 1, \\'id__2\\': 4, \\'tag_id__2\\': 8, \\'user_id__2\\': 1, \\'id__3\\': 4, \\'tag_id__3\\': 9, \\'user_id__3\\': 1, \\'id__4\\': 4, \\'tag_id__4\\': 10, \\'user_id__4\\': 1, \\'id__5\\': 4, \\'tag_id__5\\': 11, \\'user_id__5\\': 1, \\'id__6\\': 4, \\'tag_id__6\\': 12, \\'user_id__6\\': 1, \\'id__7\\': 4, \\'tag_id__7\\': 13, \\'user_id__7\\': 1, \\'id__8\\': 4, \\'tag_id__8\\': 14, \\'user_id__8\\': 1, \\'id__9\\': 4, \\'tag_id__9\\': 15, \\'user_id__9\\': 1}]\\n(Background on this error at: https://sqlalche.me/e/20/gkpj) (Background on this error at: https://sqlalche.me/e/20/7s2a)'}}\n  {'type': 'get_attribute_error', 'loc': ('response', 'user_id'), 'msg': 'Error extracting attribute: PendingRollbackError: This Session\\'s transaction has been rolled back due to a previous exception during flush. To begin a new transaction with this Session, first issue Session.rollback(). Original exception was: (psycopg2.errors.UniqueViolation) duplicate key value violates unique constraint \"tags_for_user_table_pkey\"\\nDETAIL:  Key (id)=(4) already exists.\\n\\n[SQL: INSERT INTO tags_for_user_table (id, user_id, tag_id) VALUES (%(id__0)s, %(user_id__0)s, %(tag_id__0)s), (%(id__1)s, %(user_id__1)s, %(tag_id__1)s), (%(id__2)s, %(user_id__2)s, %(tag_id__2)s), (%(id__3)s, %(user_id__3)s, %(tag_id__3)s), (%(id__4)s, %(user_id__4)s, %(tag_id__4)s), (%(id__5)s, %(user_id__5)s, %(tag_id__5)s), (%(id__6)s, %(user_id__6)s, %(tag_id__6)s), (%(id__7)s, %(user_id__7)s, %(tag_id__7)s), (%(id__8)s, %(user_id__8)s, %(tag_id__8)s), (%(id__9)s, %(user_id__9)s, %(tag_id__9)s)]\\n[parameters: {\\'id__0\\': 4, \\'tag_id__0\\': 6, \\'user_id__0\\': 1, \\'id__1\\': 4, \\'tag_id__1\\': 7, \\'user_id__1\\': 1, \\'id__2\\': 4, \\'tag_id__2\\': 8, \\'user_id__2\\': 1, \\'id__3\\': 4, \\'tag_id__3\\': 9, \\'user_id__3\\': 1, \\'id__4\\': 4, \\'tag_id__4\\': 10, \\'user_id__4\\': 1, \\'id__5\\': 4, \\'tag_id__5\\': 11, \\'user_id__5\\': 1, \\'id__6\\': 4, \\'tag_id__6\\': 12, \\'user_id__6\\': 1, \\'id__7\\': 4, \\'tag_id__7\\': 13, \\'user_id__7\\': 1, \\'id__8\\': 4, \\'tag_id__8\\': 14, \\'user_id__8\\': 1, \\'id__9\\': 4, \\'tag_id__9\\': 15, \\'user_id__9\\': 1}]\\n(Background on this error at: https://sqlalche.me/e/20/gkpj) (Background on this error at: https://sqlalche.me/e/20/7s2a)', 'input': <app.models.models.Like object at 0x00000212D3938980>, 'ctx': {'error': 'PendingRollbackError: This Session\\'s transaction has been rolled back due to a previous exception during flush. To begin a new transaction with this Session, first issue Session.rollback(). Original exception was: (psycopg2.errors.UniqueViolation) duplicate key value violates unique constraint \"tags_for_user_table_pkey\"\\nDETAIL:  Key (id)=(4) already exists.\\n\\n[SQL: INSERT INTO tags_for_user_table (id, user_id, tag_id) VALUES (%(id__0)s, %(user_id__0)s, %(tag_id__0)s), (%(id__1)s, %(user_id__1)s, %(tag_id__1)s), (%(id__2)s, %(user_id__2)s, %(tag_id__2)s), (%(id__3)s, %(user_id__3)s, %(tag_id__3)s), (%(id__4)s, %(user_id__4)s, %(tag_id__4)s), (%(id__5)s, %(user_id__5)s, %(tag_id__5)s), (%(id__6)s, %(user_id__6)s, %(tag_id__6)s), (%(id__7)s, %(user_id__7)s, %(tag_id__7)s), (%(id__8)s, %(user_id__8)s, %(tag_id__8)s), (%(id__9)s, %(user_id__9)s, %(tag_id__9)s)]\\n[parameters: {\\'id__0\\': 4, \\'tag_id__0\\': 6, \\'user_id__0\\': 1, \\'id__1\\': 4, \\'tag_id__1\\': 7, \\'user_id__1\\': 1, \\'id__2\\': 4, \\'tag_id__2\\': 8, \\'user_id__2\\': 1, \\'id__3\\': 4, \\'tag_id__3\\': 9, \\'user_id__3\\': 1, \\'id__4\\': 4, \\'tag_id__4\\': 10, \\'user_id__4\\': 1, \\'id__5\\': 4, \\'tag_id__5\\': 11, \\'user_id__5\\': 1, \\'id__6\\': 4, \\'tag_id__6\\': 12, \\'user_id__6\\': 1, \\'id__7\\': 4, \\'tag_id__7\\': 13, \\'user_id__7\\': 1, \\'id__8\\': 4, \\'tag_id__8\\': 14, \\'user_id__8\\': 1, \\'id__9\\': 4, \\'tag_id__9\\': 15, \\'user_id__9\\': 1}]\\n(Background on this error at: https://sqlalche.me/e/20/gkpj) (Background on this error at: https://sqlalche.me/e/20/7s2a)'}}\n  {'type': 'get_attribute_error', 'loc': ('response', 'like_id'), 'msg': 'Error extracting attribute: PendingRollbackError: This Session\\'s transaction has been rolled back due to a previous exception during flush. To begin a new transaction with this Session, first issue Session.rollback(). Original exception was: (psycopg2.errors.UniqueViolation) duplicate key value violates unique constraint \"tags_for_user_table_pkey\"\\nDETAIL:  Key (id)=(4) already exists.\\n\\n[SQL: INSERT INTO tags_for_user_table (id, user_id, tag_id) VALUES (%(id__0)s, %(user_id__0)s, %(tag_id__0)s), (%(id__1)s, %(user_id__1)s, %(tag_id__1)s), (%(id__2)s, %(user_id__2)s, %(tag_id__2)s), (%(id__3)s, %(user_id__3)s, %(tag_id__3)s), (%(id__4)s, %(user_id__4)s, %(tag_id__4)s), (%(id__5)s, %(user_id__5)s, %(tag_id__5)s), (%(id__6)s, %(user_id__6)s, %(tag_id__6)s), (%(id__7)s, %(user_id__7)s, %(tag_id__7)s), (%(id__8)s, %(user_id__8)s, %(tag_id__8)s), (%(id__9)s, %(user_id__9)s, %(tag_id__9)s)]\\n[parameters: {\\'id__0\\': 4, \\'tag_id__0\\': 6, \\'user_id__0\\': 1, \\'id__1\\': 4, \\'tag_id__1\\': 7, \\'user_id__1\\': 1, \\'id__2\\': 4, \\'tag_id__2\\': 8, \\'user_id__2\\': 1, \\'id__3\\': 4, \\'tag_id__3\\': 9, \\'user_id__3\\': 1, \\'id__4\\': 4, \\'tag_id__4\\': 10, \\'user_id__4\\': 1, \\'id__5\\': 4, \\'tag_id__5\\': 11, \\'user_id__5\\': 1, \\'id__6\\': 4, \\'tag_id__6\\': 12, \\'user_id__6\\': 1, \\'id__7\\': 4, \\'tag_id__7\\': 13, \\'user_id__7\\': 1, \\'id__8\\': 4, \\'tag_id__8\\': 14, \\'user_id__8\\': 1, \\'id__9\\': 4, \\'tag_id__9\\': 15, \\'user_id__9\\': 1}]\\n(Background on this error at: https://sqlalche.me/e/20/gkpj) (Background on this error at: https://sqlalche.me/e/20/7s2a)', 'input': <app.models.models.Like object at 0x00000212D3938980>, 'ctx': {'error': 'PendingRollbackError: This Session\\'s transaction has been rolled back due to a previous exception during flush. To begin a new transaction with this Session, first issue Session.rollback(). Original exception was: (psycopg2.errors.UniqueViolation) duplicate key value violates unique constraint \"tags_for_user_table_pkey\"\\nDETAIL:  Key (id)=(4) already exists.\\n\\n[SQL: INSERT INTO tags_for_user_table (id, user_id, tag_id) VALUES (%(id__0)s, %(user_id__0)s, %(tag_id__0)s), (%(id__1)s, %(user_id__1)s, %(tag_id__1)s), (%(id__2)s, %(user_id__2)s, %(tag_id__2)s), (%(id__3)s, %(user_id__3)s, %(tag_id__3)s), (%(id__4)s, %(user_id__4)s, %(tag_id__4)s), (%(id__5)s, %(user_id__5)s, %(tag_id__5)s), (%(id__6)s, %(user_id__6)s, %(tag_id__6)s), (%(id__7)s, %(user_id__7)s, %(tag_id__7)s), (%(id__8)s, %(user_id__8)s, %(tag_id__8)s), (%(id__9)s, %(user_id__9)s, %(tag_id__9)s)]\\n[parameters: {\\'id__0\\': 4, \\'tag_id__0\\': 6, \\'user_id__0\\': 1, \\'id__1\\': 4, \\'tag_id__1\\': 7, \\'user_id__1\\': 1, \\'id__2\\': 4, \\'tag_id__2\\': 8, \\'user_id__2\\': 1, \\'id__3\\': 4, \\'tag_id__3\\': 9, \\'user_id__3\\': 1, \\'id__4\\': 4, \\'tag_id__4\\': 10, \\'user_id__4\\': 1, \\'id__5\\': 4, \\'tag_id__5\\': 11, \\'user_id__5\\': 1, \\'id__6\\': 4, \\'tag_id__6\\': 12, \\'user_id__6\\': 1, \\'id__7\\': 4, \\'tag_id__7\\': 13, \\'user_id__7\\': 1, \\'id__8\\': 4, \\'tag_id__8\\': 14, \\'user_id__8\\': 1, \\'id__9\\': 4, \\'tag_id__9\\': 15, \\'user_id__9\\': 1}]\\n(Background on this error at: https://sqlalche.me/e/20/gkpj) (Background on this error at: https://sqlalche.me/e/20/7s2a)'}}\n\n"
}